Workbook

Sheet Summary
A7: Job Name: | B7: MCCC LA
A9: Job Number:
A11: Job Description:
A13: Location:
A15: Date: | B15: 46012
A17: Quote Breakdown
A19: QTY | B19: Location | C19: Tech Hours | D19: Other 3rd Party Cost | E19: Mech Cont Cost | F19: Material Cost | G19: AME Tech Cost | H19: AME PM Cost | I19: Engineering Cost | J19: Electrical Cost | L19: Margin | M19: Total Sell Price
A21: 1 | B21: MCCC LA | C21: ='Price Sheet 1'!B401 -> 0 | D21: ='Price Sheet 1'!E425 -> 0 | E21: ='Price Sheet 1'!E424 -> 0 | F21: ='Price Sheet 1'!E413 -> 0 | G21: ='Price Sheet 1'!E414 -> 0 | H21: ='Price Sheet 1'!E415 -> 0 | I21: ='Price Sheet 1'!E416 -> 0 | J21: ='Price Sheet 1'!E431 -> 0 | L21: ='Price Sheet 1'!E437 -> #DIV/0! | M21: ='Price Sheet 1'!E436 -> 0
A22: 1 | C22: ='Price Sheet 2'!B401 -> 0 | D22: ='Price Sheet 2'!E425 -> 0 | E22: ='Price Sheet 2'!E424 -> 0 | F22: ='Price Sheet 2'!E413 -> 0 | G22: ='Price Sheet 2'!E414 -> 0 | H22: ='Price Sheet 2'!E415 -> 0 | I22: ='Price Sheet 2'!E416 -> 0 | J22: ='Price Sheet 2'!E431 -> 0 | L22: ='Price Sheet 2'!E437 -> #DIV/0! | M22: ='Price Sheet 2'!E436 -> 0
A23: 1 | C23: ='Price Sheet 3'!B401 -> 0 | D23: ='Price Sheet 3'!E425 -> 0 | E23: ='Price Sheet 3'!E424 -> 0 | F23: ='Price Sheet 3'!E413 -> 0 | G23: ='Price Sheet 3'!E414 -> 0 | H23: ='Price Sheet 3'!E415 -> 0 | I23: ='Price Sheet 3'!E416 -> 0 | J23: ='Price Sheet 3'!E431 -> 0 | L23: ='Price Sheet 3'!E437 -> #DIV/0! | M23: ='Price Sheet 3'!E436 -> 0
A24: 1 | C24: ='Price Sheet 4'!B401 -> 0 | D24: ='Price Sheet 4'!E425 -> 0 | E24: ='Price Sheet 4'!E424 -> 0 | F24: ='Price Sheet 4'!E413 -> 0 | G24: ='Price Sheet 4'!E414 -> 0 | H24: ='Price Sheet 4'!E415 -> 0 | I24: ='Price Sheet 4'!E416 -> 0 | J24: ='Price Sheet 4'!E431 -> 0 | L24: ='Price Sheet 4'!E437 -> #DIV/0! | M24: ='Price Sheet 4'!E436 -> 0
A25: 1 | C25: ='Price Sheet 5'!B401 -> 0 | D25: ='Price Sheet 5'!E425 -> 0 | E25: ='Price Sheet 5'!E424 -> 0 | F25: ='Price Sheet 5'!E413 -> 0 | G25: ='Price Sheet 5'!E414 -> 0 | H25: ='Price Sheet 5'!E415 -> 0 | I25: ='Price Sheet 5'!E416 -> 0 | J25: ='Price Sheet 5'!E431 -> 0 | L25: ='Price Sheet 5'!E437 -> #DIV/0! | M25: ='Price Sheet 5'!E436 -> 0
A26: 1 | C26: ='Price Sheet 6'!B401 -> 0 | D26: ='Price Sheet 6'!E425 -> 0 | E26: ='Price Sheet 6'!E424 -> 0 | F26: ='Price Sheet 6'!E413 -> 0 | G26: ='Price Sheet 6'!E414 -> 0 | H26: ='Price Sheet 6'!E415 -> 0 | I26: ='Price Sheet 6'!E416 -> 0 | J26: ='Price Sheet 6'!E431 -> 0 | L26: ='Price Sheet 6'!E437 -> #DIV/0! | M26: ='Price Sheet 6'!E436 -> 0
A27: 1 | C27: ='Price Sheet 7'!B401 -> 0 | D27: ='Price Sheet 7'!E425 -> 0 | E27: ='Price Sheet 7'!E424 -> 0 | F27: ='Price Sheet 7'!E413 -> 0 | G27: ='Price Sheet 7'!E414 -> 0 | H27: ='Price Sheet 7'!E415 -> 0 | I27: ='Price Sheet 7'!E416 -> 0 | J27: ='Price Sheet 7'!E431 -> 0 | L27: ='Price Sheet 7'!E437 -> #DIV/0! | M27: ='Price Sheet 7'!E436 -> 0
A28: 1 | C28: ='Price Sheet 8'!B401 -> 0 | D28: ='Price Sheet 8'!E425 -> 0 | E28: ='Price Sheet 8'!E424 -> 0 | F28: ='Price Sheet 8'!E413 -> 0 | G28: ='Price Sheet 8'!E414 -> 0 | H28: ='Price Sheet 8'!E415 -> 0 | I28: ='Price Sheet 8'!E416 -> 0 | J28: ='Price Sheet 8'!E431 -> 0 | L28: ='Price Sheet 8'!E437 -> #DIV/0! | M28: ='Price Sheet 8'!E436 -> 0
A29: 1 | C29: ='Price Sheet 9'!B401 -> 0 | D29: ='Price Sheet 9'!E425 -> 0 | E29: ='Price Sheet 9'!E424 -> 0 | F29: ='Price Sheet 9'!E413 -> 0 | G29: ='Price Sheet 9'!E414 -> 0 | H29: ='Price Sheet 9'!E415 -> 0 | I29: ='Price Sheet 9'!E416 -> 0 | J29: ='Price Sheet 9'!E431 -> 0 | L29: ='Price Sheet 9'!E437 -> #DIV/0! | M29: ='Price Sheet 9'!E436 -> 0
A30: 1 | C30: ='Price Sheet 10'!B401 -> 0 | D30: ='Price Sheet 10'!E425 -> 0 | E30: ='Price Sheet 10'!E424 -> 0 | F30: ='Price Sheet 10'!E413 -> 0 | G30: ='Price Sheet 10'!E414 -> 0 | H30: ='Price Sheet 10'!E415 -> 0 | I30: ='Price Sheet 10'!E416 -> 0 | J30: ='Price Sheet 10'!E431 -> 0 | L30: ='Price Sheet 10'!E437 -> #DIV/0! | M30: ='Price Sheet 10'!E436 -> 0
B32: Total | C32: =SUM(C21:C31) -> 0 | D32: =SUM(D21:D31) -> 0 | E32: =SUM(E21:E31) -> 0 | F32: =SUM(F20:F31) -> 0 | G32: =SUM(G20:G31) -> 0 | H32: =SUM(H20:H31) -> 0 | I32: =SUM(I20:I31) -> 0 | J32: =SUM(J20:J31) -> 0 | L32: =AVERAGE(L21:L31) -> #DIV/0! | M32: =SUM(M21:M31) -> 0
B35: AME Material / Tech / PM / Engineering Total Costs | C35: =F32+G32+H32+I32 -> 0
B36: Markup | C36: 0.4
B37: Sell Price | C37: =C35*(1+C36) -> 0
B40: Mechanical Contractor Costs | C40: =E32 -> 0
B41: Other 3rd Party Costs | C41: =D32 -> 0
B42: Markup | C42: 0.25
B43: Sell Price | C43: =(C40+C41)*(1+C42) -> 0
B46: Electrical Total Costs | C46: =J32 -> 0
B47: Markup | C47: 0.25
B48: Sell Price | C48: =C46*(1+C47) -> 0
B51: Total Sell Price | C51: =C37+C43+C48 -> 0
B52: Gross Margin | C52: =(C51-(C35+C40+C41+C46))/C51 -> #DIV/0!

Sheet Price Sheet 1
B4: Tech Hours | C4: Quantities | D4: Scope of Work | E4: Unit Price | F4: Material Totals | G4: Electric Costs
F6: =E6*C6 -> 0
F7: =E7*C7 -> 0
F8: =E8*C8 -> 0
F9: =E9*C9 -> 0
F10: =E10*C10 -> 0
F11: =E11*C11 -> 0
F12: =E12*C12 -> 0
F13: =E13*C13 -> 0
F14: =E14*C14 -> 0
F15: =E15*C15 -> 0
F16: =E16*C16 -> 0
F17: =E17*C17 -> 0
... F396: =E396*C396 -> 0
B401: =SUM(B4:B400) -> 0 | F401: =SUM(F6:F400) -> 0 | G401: =SUM(G4:G400) -> 0
D403: Additional Material Contingency | E403: 0.1
D404: Tech Cost Per Hour | E404: 110
D405: AME Project Management Costs in Comparison to Technician Costs | E405: 0.4
D406: AME Engineering Costs in Comparison to Technician Costs | E406: 0.2
D409: Material Sales Tax | E409: 0.06625 | G409: Sales Tax | H409: Cost
D410: Material Sales Tax Total | E410: =F401*E409 -> 0 | G410: New Jersey | H410: 0.06625
G411: New York | H411: 0.08875
D413: Total Material Costs | E413: =F401*(1+E403) -> 0
D414: AME Technician Costs | E414: =B401*E404 -> 0
D415: AME Project Management Costs | E415: =E414*E405 -> 0
D416: Engineering Costs | E416: =E414*E406 -> 0
D417: Total AME Costs | E417: =SUM(E413:E416) -> 0
D420: Markup on Total Costs | E420: 0.4
D421: AME Material / Technician / PM / Engineering Sell Price | E421: =E417*(1+E420) -> 0
D424: Mechanical Contractor Costs
D425: Other 3rd Party Costs
D426: Markup on Contractor Costs | E426: 0.25
D427: Third Party Contractors Sell Price | E427: =(E424+E425)*(1+E426) -> 0
D430: Markup on Internal Electrical Budget | E430: 0.1 | G430: Electrician | H430: Cost
D431: Electrical Costs | E431: =G401*(1+E430) -> 0
D432: Markup on Electrical Costs | E432: 0.25
D433: Electrical Sell Price | E433: =E431*(1+E432) -> 0
D436: TOTAL SELL PRICE | E436: =E421+E433+E410+E427 -> 0
D437: GROSS MARGIN | E437: =(E436-E410-(E431+E417))/(E436-E410) -> #DIV/0!
D440: Markup on Total Sell Price | E440: 0.15
...

Sheet Price Sheet 2
B4: Tech Hours | C4: Quantities | D4: Scope of Work | E4: Unit Price | F4: Material Totals | G4: Electric Costs
F6: =E6*C6 -> 0
F7: =E7*C7 -> 0
F8: =E8*C8 -> 0
F9: =E9*C9 -> 0
F10: =E10*C10 -> 0
F11: =E11*C11 -> 0
F12: =E12*C12 -> 0
F13: =E13*C13 -> 0
F14: =E14*C14 -> 0
F15: =E15*C15 -> 0
F16: =E16*C16 -> 0
F17: =E17*C17 -> 0
... F396: =E396*C396 -> 0
B401: =SUM(B4:B400) -> 0 | F401: =SUM(F6:F400) -> 0 | G401: =SUM(G4:G400) -> 0
D403: Additional Material Contingency | E403: 0.1
D404: Tech Cost Per Hour | E404: 110
D405: AME Project Management Costs in Comparison to Technician Costs | E405: 0.4
D406: AME Engineering Costs in Comparison to Technician Costs | E406: 0.2
D409: Material Sales Tax | E409: 0.06625 | G409: Sales Tax | H409: Cost
D410: Material Sales Tax Total | E410: =F401*E409 -> 0 | G410: New Jersey | H410: 0.06625
G411: New York | H411: 0.08875
D413: Total Material Costs | E413: =F401*(1+E403) -> 0
D414: AME Technician Costs | E414: =B401*E404 -> 0
D415: AME Project Management Costs | E415: =E414*E405 -> 0
D416: Engineering Costs | E416: =E414*E406 -> 0
D417: Total AME Costs | E417: =SUM(E413:E416) -> 0
D420: Markup on Total Costs | E420: 0.4
D421: AME Material / Technician / PM / Engineering Sell Price | E421: =E417*(1+E420) -> 0
D424: Mechanical Contractor Costs
D425: Other 3rd Party Costs
D426: Markup on Contractor Costs | E426: 0.25
D427: Third Party Contractors Sell Price | E427: =(E424+E425)*(1+E426) -> 0
D430: Markup on Internal Electrical Budget | E430: 0.1 | G430: Electrician | H430: Cost
D431: Electrical Costs | E431: =G401*(1+E430) -> 0
D432: Markup on Electrical Costs | E432: 0.25
D433: Electrical Sell Price | E433: =E431*(1+E432) -> 0
D436: TOTAL SELL PRICE | E436: =E421+E433+E410+E427 -> 0
D437: GROSS MARGIN | E437: =(E436-(E431+E417))/E436 -> #DIV/0!
D440: Markup on Total Sell Price | E440: 0.15
...

Sheet Price Sheet 3
B4: Tech Hours | C4: Quantities | D4: Scope of Work | E4: Unit Price | F4: Material Totals | G4: Electric Costs
F6: =E6*C6 -> 0
F7: =E7*C7 -> 0
F8: =E8*C8 -> 0
F9: =E9*C9 -> 0
F10: =E10*C10 -> 0
F11: =E11*C11 -> 0
F12: =E12*C12 -> 0
F13: =E13*C13 -> 0
F14: =E14*C14 -> 0
F15: =E15*C15 -> 0
F16: =E16*C16 -> 0
F17: =E17*C17 -> 0
... F396: =E396*C396 -> 0
B401: =SUM(B4:B400) -> 0 | F401: =SUM(F6:F400) -> 0 | G401: =SUM(G4:G400) -> 0
D403: Additional Material Contingency | E403: 0.1
D404: Tech Cost Per Hour | E404: 110
D405: AME Project Management Costs in Comparison to Technician Costs | E405: 0.4
D406: AME Engineering Costs in Comparison to Technician Costs | E406: 0.2
D409: Material Sales Tax | E409: 0.06625 | G409: Sales Tax | H409: Cost
D410: Material Sales Tax Total | E410: =F401*E409 -> 0 | G410: New Jersey | H410: 0.06625
G411: New York | H411: 0.08875
D413: Total Material Costs | E413: =F401*(1+E403) -> 0
D414: AME Technician Costs | E414: =B401*E404 -> 0
D415: AME Project Management Costs | E415: =E414*E405 -> 0
D416: Engineering Costs | E416: =E414*E406 -> 0
D417: Total AME Costs | E417: =SUM(E413:E416) -> 0
D420: Markup on Total Costs | E420: 0.4
D421: AME Material / Technician / PM / Engineering Sell Price | E421: =E417*(1+E420) -> 0
D424: Mechanical Contractor Costs
D425: Other 3rd Party Costs
D426: Markup on Contractor Costs | E426: 0.25
D427: Third Party Contractors Sell Price | E427: =(E424+E425)*(1+E426) -> 0
D430: Markup on Internal Electrical Budget | E430: 0.1 | G430: Electrician | H430: Cost
D431: Electrical Costs | E431: =G401*(1+E430) -> 0
D432: Markup on Electrical Costs | E432: 0.25
D433: Electrical Sell Price | E433: =E431*(1+E432) -> 0
D436: TOTAL SELL PRICE | E436: =E421+E433+E410+E427 -> 0
D437: GROSS MARGIN | E437: =(E436-(E431+E417))/E436 -> #DIV/0!
D440: Markup on Total Sell Price | E440: 0.15
...

Sheet Price Sheet 4
B4: Tech Hours | C4: Quantities | D4: Scope of Work | E4: Unit Price | F4: Material Totals | G4: Electric Costs
F6: =E6*C6 -> 0
F7: =E7*C7 -> 0
F8: =E8*C8 -> 0
F9: =E9*C9 -> 0
F10: =E10*C10 -> 0
F11: =E11*C11 -> 0
F12: =E12*C12 -> 0
F13: =E13*C13 -> 0
F14: =E14*C14 -> 0
F15: =E15*C15 -> 0
F16: =E16*C16 -> 0
F17: =E17*C17 -> 0
... F396: =E396*C396 -> 0
B401: =SUM(B4:B400) -> 0 | F401: =SUM(F6:F400) -> 0 | G401: =SUM(G4:G400) -> 0
D403: Additional Material Contingency | E403: 0.1
D404: Tech Cost Per Hour | E404: 110
D405: AME Project Management Costs in Comparison to Technician Costs | E405: 0.4
D406: AME Engineering Costs in Comparison to Technician Costs | E406: 0.2
D409: Material Sales Tax | E409: 0.06625 | G409: Sales Tax | H409: Cost
D410: Material Sales Tax Total | E410: =F401*E409 -> 0 | G410: New Jersey | H410: 0.06625
G411: New York | H411: 0.08875
D413: Total Material Costs | E413: =F401*(1+E403) -> 0
D414: AME Technician Costs | E414: =B401*E404 -> 0
D415: AME Project Management Costs | E415: =E414*E405 -> 0
D416: Engineering Costs | E416: =E414*E406 -> 0
D417: Total AME Costs | E417: =SUM(E413:E416) -> 0
D420: Markup on Total Costs | E420: 0.4
D421: AME Material / Technician / PM / Engineering Sell Price | E421: =E417*(1+E420) -> 0
D424: Mechanical Contractor Costs
D425: Other 3rd Party Costs
D426: Markup on Contractor Costs | E426: 0.25
D427: Third Party Contractors Sell Price | E427: =(E424+E425)*(1+E426) -> 0
D430: Markup on Internal Electrical Budget | E430: 0.1 | G430: Electrician | H430: Cost
D431: Electrical Costs | E431: =G401*(1+E430) -> 0
D432: Markup on Electrical Costs | E432: 0.25
D433: Electrical Sell Price | E433: =E431*(1+E432) -> 0
D436: TOTAL SELL PRICE | E436: =E421+E433+E410+E427 -> 0
D437: GROSS MARGIN | E437: =(E436-(E431+E417))/E436 -> #DIV/0!
D440: Markup on Total Sell Price | E440: 0.15
...

Sheet Price Sheet 5
B4: Tech Hours | C4: Quantities | D4: Scope of Work | E4: Unit Price | F4: Material Totals | G4: Electric Costs
F6: =E6*C6 -> 0
F7: =E7*C7 -> 0
F8: =E8*C8 -> 0
F9: =E9*C9 -> 0
F10: =E10*C10 -> 0
F11: =E11*C11 -> 0
F12: =E12*C12 -> 0
F13: =E13*C13 -> 0
F14: =E14*C14 -> 0
F15: =E15*C15 -> 0
F16: =E16*C16 -> 0
F17: =E17*C17 -> 0
... F396: =E396*C396 -> 0
B401: =SUM(B4:B400) -> 0 | F401: =SUM(F6:F400) -> 0 | G401: =SUM(G4:G400) -> 0
D403: Additional Material Contingency | E403: 0.1
D404: Tech Cost Per Hour | E404: 110
D405: AME Project Management Costs in Comparison to Technician Costs | E405: 0.4
D406: AME Engineering Costs in Comparison to Technician Costs | E406: 0.2
D409: Material Sales Tax | E409: 0.06625 | G409: Sales Tax | H409: Cost
D410: Material Sales Tax Total | E410: =F401*E409 -> 0 | G410: New Jersey | H410: 0.06625
G411: New York | H411: 0.08875
D413: Total Material Costs | E413: =F401*(1+E403) -> 0
D414: AME Technician Costs | E414: =B401*E404 -> 0
D415: AME Project Management Costs | E415: =E414*E405 -> 0
D416: Engineering Costs | E416: =E414*E406 -> 0
D417: Total AME Costs | E417: =SUM(E413:E416) -> 0
D420: Markup on Total Costs | E420: 0.4
D421: AME Material / Technician / PM / Engineering Sell Price | E421: =E417*(1+E420) -> 0
D424: Mechanical Contractor Costs
D425: Other 3rd Party Costs
D426: Markup on Contractor Costs | E426: 0.25
D427: Third Party Contractors Sell Price | E427: =(E424+E425)*(1+E426) -> 0
D430: Markup on Internal Electrical Budget | E430: 0.1 | G430: Electrician | H430: Cost
D431: Electrical Costs | E431: =G401*(1+E430) -> 0
D432: Markup on Electrical Costs | E432: 0.25
D433: Electrical Sell Price | E433: =E431*(1+E432) -> 0
D436: TOTAL SELL PRICE | E436: =E421+E433+E410+E427 -> 0
D437: GROSS MARGIN | E437: =(E436-(E431+E417))/E436 -> #DIV/0!
D440: Markup on Total Sell Price | E440: 0.15
...

Sheet Price Sheet 6
B4: Tech Hours | C4: Quantities | D4: Scope of Work | E4: Unit Price | F4: Material Totals | G4: Electric Costs
F6: =E6*C6 -> 0
F7: =E7*C7 -> 0
F8: =E8*C8 -> 0
F9: =E9*C9 -> 0
F10: =E10*C10 -> 0
F11: =E11*C11 -> 0
F12: =E12*C12 -> 0
F13: =E13*C13 -> 0
F14: =E14*C14 -> 0
F15: =E15*C15 -> 0
F16: =E16*C16 -> 0
F17: =E17*C17 -> 0
... F396: =E396*C396 -> 0
B401: =SUM(B4:B400) -> 0 | F401: =SUM(F6:F400) -> 0 | G401: =SUM(G4:G400) -> 0
D403: Additional Material Contingency | E403: 0.1
D404: Tech Cost Per Hour | E404: 110
D405: AME Project Management Costs in Comparison to Technician Costs | E405: 0.4
D406: AME Engineering Costs in Comparison to Technician Costs | E406: 0.2
D409: Material Sales Tax | E409: 0.06625 | G409: Sales Tax | H409: Cost
D410: Material Sales Tax Total | E410: =F401*E409 -> 0 | G410: New Jersey | H410: 0.06625
G411: New York | H411: 0.08875
D413: Total Material Costs | E413: =F401*(1+E403) -> 0
D414: AME Technician Costs | E414: =B401*E404 -> 0
D415: AME Project Management Costs | E415: =E414*E405 -> 0
D416: Engineering Costs | E416: =E414*E406 -> 0
D417: Total AME Costs | E417: =SUM(E413:E416) -> 0
D420: Markup on Total Costs | E420: 0.4
D421: AME Material / Technician / PM / Engineering Sell Price | E421: =E417*(1+E420) -> 0
D424: Mechanical Contractor Costs
D425: Other 3rd Party Costs
D426: Markup on Contractor Costs | E426: 0.25
D427: Third Party Contractors Sell Price | E427: =(E424+E425)*(1+E426) -> 0
D430: Markup on Internal Electrical Budget | E430: 0.1 | G430: Electrician | H430: Cost
D431: Electrical Costs | E431: =G401*(1+E430) -> 0
D432: Markup on Electrical Costs | E432: 0.25
D433: Electrical Sell Price | E433: =E431*(1+E432) -> 0
D436: TOTAL SELL PRICE | E436: =E421+E433+E410+E427 -> 0
D437: GROSS MARGIN | E437: =(E436-(E431+E417))/E436 -> #DIV/0!
D440: Markup on Total Sell Price | E440: 0.15
...

Sheet Price Sheet 7
B4: Tech Hours | C4: Quantities | D4: Scope of Work | E4: Unit Price | F4: Material Totals | G4: Electric Costs
F6: =E6*C6 -> 0
F7: =E7*C7 -> 0
F8: =E8*C8 -> 0
F9: =E9*C9 -> 0
F10: =E10*C10 -> 0
F11: =E11*C11 -> 0
F12: =E12*C12 -> 0
F13: =E13*C13 -> 0
F14: =E14*C14 -> 0
F15: =E15*C15 -> 0
F16: =E16*C16 -> 0
F17: =E17*C17 -> 0
... F396: =E396*C396 -> 0
B401: =SUM(B4:B400) -> 0 | F401: =SUM(F6:F400) -> 0 | G401: =SUM(G4:G400) -> 0
D403: Additional Material Contingency | E403: 0.1
D404: Tech Cost Per Hour | E404: 110
D405: AME Project Management Costs in Comparison to Technician Costs | E405: 0.4
D406: AME Engineering Costs in Comparison to Technician Costs | E406: 0.2
D409: Material Sales Tax | E409: 0.06625 | G409: Sales Tax | H409: Cost
D410: Material Sales Tax Total | E410: =F401*E409 -> 0 | G410: New Jersey | H410: 0.06625
G411: New York | H411: 0.08875
D413: Total Material Costs | E413: =F401*(1+E403) -> 0
D414: AME Technician Costs | E414: =B401*E404 -> 0
D415: AME Project Management Costs | E415: =E414*E405 -> 0
D416: Engineering Costs | E416: =E414*E406 -> 0
D417: Total AME Costs | E417: =SUM(E413:E416) -> 0
D420: Markup on Total Costs | E420: 0.4
D421: AME Material / Technician / PM / Engineering Sell Price | E421: =E417*(1+E420) -> 0
D424: Mechanical Contractor Costs
D425: Other 3rd Party Costs
D426: Markup on Contractor Costs | E426: 0.25
D427: Third Party Contractors Sell Price | E427: =(E424+E425)*(1+E426) -> 0
D430: Markup on Internal Electrical Budget | E430: 0.1 | G430: Electrician | H430: Cost
D431: Electrical Costs | E431: =G401*(1+E430) -> 0
D432: Markup on Electrical Costs | E432: 0.25
D433: Electrical Sell Price | E433: =E431*(1+E432) -> 0
D436: TOTAL SELL PRICE | E436: =E421+E433+E410+E427 -> 0
D437: GROSS MARGIN | E437: =(E436-(E431+E417))/E436 -> #DIV/0!
D440: Markup on Total Sell Price | E440: 0.15
...

Sheet Price Sheet 8
B4: Tech Hours | C4: Quantities | D4: Scope of Work | E4: Unit Price | F4: Material Totals | G4: Electric Costs
F6: =E6*C6 -> 0
F7: =E7*C7 -> 0
F8: =E8*C8 -> 0
F9: =E9*C9 -> 0
F10: =E10*C10 -> 0
F11: =E11*C11 -> 0
F12: =E12*C12 -> 0
F13: =E13*C13 -> 0
F14: =E14*C14 -> 0
F15: =E15*C15 -> 0
F16: =E16*C16 -> 0
F17: =E17*C17 -> 0
... F396: =E396*C396 -> 0
B401: =SUM(B4:B400) -> 0 | F401: =SUM(F6:F400) -> 0 | G401: =SUM(G4:G400) -> 0
D403: Additional Material Contingency | E403: 0.1
D404: Tech Cost Per Hour | E404: 110
D405: AME Project Management Costs in Comparison to Technician Costs | E405: 0.4
D406: AME Engineering Costs in Comparison to Technician Costs | E406: 0.2
D409: Material Sales Tax | E409: 0.06625 | G409: Sales Tax | H409: Cost
D410: Material Sales Tax Total | E410: =F401*E409 -> 0 | G410: New Jersey | H410: 0.06625
G411: New York | H411: 0.08875
D413: Total Material Costs | E413: =F401*(1+E403) -> 0
D414: AME Technician Costs | E414: =B401*E404 -> 0
D415: AME Project Management Costs | E415: =E414*E405 -> 0
D416: Engineering Costs | E416: =E414*E406 -> 0
D417: Total AME Costs | E417: =SUM(E413:E416) -> 0
D420: Markup on Total Costs | E420: 0.4
D421: AME Material / Technician / PM / Engineering Sell Price | E421: =E417*(1+E420) -> 0
D424: Mechanical Contractor Costs
D425: Other 3rd Party Costs
D426: Markup on Contractor Costs | E426: 0.25
D427: Third Party Contractors Sell Price | E427: =(E424+E425)*(1+E426) -> 0
D430: Markup on Internal Electrical Budget | E430: 0.1 | G430: Electrician | H430: Cost
D431: Electrical Costs | E431: =G401*(1+E430) -> 0
D432: Markup on Electrical Costs | E432: 0.25
D433: Electrical Sell Price | E433: =E431*(1+E432) -> 0
D436: TOTAL SELL PRICE | E436: =E421+E433+E410+E427 -> 0
D437: GROSS MARGIN | E437: =(E436-(E431+E417))/E436 -> #DIV/0!
D440: Markup on Total Sell Price | E440: 0.15
...

Sheet Price Sheet 9
B4: Tech Hours | C4: Quantities | D4: Scope of Work | E4: Unit Price | F4: Material Totals | G4: Electric Costs
F6: =E6*C6 -> 0
F7: =E7*C7 -> 0
F8: =E8*C8 -> 0
F9: =E9*C9 -> 0
F10: =E10*C10 -> 0
F11: =E11*C11 -> 0
F12: =E12*C12 -> 0
F13: =E13*C13 -> 0
F14: =E14*C14 -> 0
F15: =E15*C15 -> 0
F16: =E16*C16 -> 0
F17: =E17*C17 -> 0
... F396: =E396*C396 -> 0
B401: =SUM(B4:B400) -> 0 | F401: =SUM(F6:F400) -> 0 | G401: =SUM(G4:G400) -> 0
D403: Additional Material Contingency | E403: 0.1
D404: Tech Cost Per Hour | E404: 110
D405: AME Project Management Costs in Comparison to Technician Costs | E405: 0.4
D406: AME Engineering Costs in Comparison to Technician Costs | E406: 0.2
D409: Material Sales Tax | E409: 0.06625 | G409: Sales Tax | H409: Cost
D410: Material Sales Tax Total | E410: =F401*E409 -> 0 | G410: New Jersey | H410: 0.06625
G411: New York | H411: 0.08875
D413: Total Material Costs | E413: =F401*(1+E403) -> 0
D414: AME Technician Costs | E414: =B401*E404 -> 0
D415: AME Project Management Costs | E415: =E414*E405 -> 0
D416: Engineering Costs | E416: =E414*E406 -> 0
D417: Total AME Costs | E417: =SUM(E413:E416) -> 0
D420: Markup on Total Costs | E420: 0.4
D421: AME Material / Technician / PM / Engineering Sell Price | E421: =E417*(1+E420) -> 0
D424: Mechanical Contractor Costs
D425: Other 3rd Party Costs
D426: Markup on Contractor Costs | E426: 0.25
D427: Third Party Contractors Sell Price | E427: =(E424+E425)*(1+E426) -> 0
D430: Markup on Internal Electrical Budget | E430: 0.1 | G430: Electrician | H430: Cost
D431: Electrical Costs | E431: =G401*(1+E430) -> 0
D432: Markup on Electrical Costs | E432: 0.25
D433: Electrical Sell Price | E433: =E431*(1+E432) -> 0
D436: TOTAL SELL PRICE | E436: =E421+E433+E410+E427 -> 0
D437: GROSS MARGIN | E437: =(E436-(E431+E417))/E436 -> #DIV/0!
D440: Markup on Total Sell Price | E440: 0.15
...

Sheet Price Sheet 10
B4: Tech Hours | C4: Quantities | D4: Scope of Work | E4: Unit Price | F4: Material Totals | G4: Electric Costs
F6: =E6*C6 -> 0
F7: =E7*C7 -> 0
F8: =E8*C8 -> 0
F9: =E9*C9 -> 0
F10: =E10*C10 -> 0
F11: =E11*C11 -> 0
F12: =E12*C12 -> 0
F13: =E13*C13 -> 0
F14: =E14*C14 -> 0
F15: =E15*C15 -> 0
F16: =E16*C16 -> 0
F17: =E17*C17 -> 0
... F396: =E396*C396 -> 0
B401: =SUM(B4:B400) -> 0 | F401: =SUM(F6:F400) -> 0 | G401: =SUM(G4:G400) -> 0
D403: Additional Material Contingency | E403: 0.1
D404: Tech Cost Per Hour | E404: 110
D405: AME Project Management Costs in Comparison to Technician Costs | E405: 0.4
D406: AME Engineering Costs in Comparison to Technician Costs | E406: 0.2
D409: Material Sales Tax | E409: 0.06625 | G409: Sales Tax | H409: Cost
D410: Material Sales Tax Total | E410: =F401*E409 -> 0 | G410: New Jersey | H410: 0.06625
G411: New York | H411: 0.08875
D413: Total Material Costs | E413: =F401*(1+E403) -> 0
D414: AME Technician Costs | E414: =B401*E404 -> 0
D415: AME Project Management Costs | E415: =E414*E405 -> 0
D416: Engineering Costs | E416: =E414*E406 -> 0
D417: Total AME Costs | E417: =SUM(E413:E416) -> 0
D420: Markup on Total Costs | E420: 0.4
D421: AME Material / Technician / PM / Engineering Sell Price | E421: =E417*(1+E420) -> 0
D424: Mechanical Contractor Costs
D425: Other 3rd Party Costs
D426: Markup on Contractor Costs | E426: 0.25
D427: Third Party Contractors Sell Price | E427: =(E424+E425)*(1+E426) -> 0
D430: Markup on Internal Electrical Budget | E430: 0.1 | G430: Electrician | H430: Cost
D431: Electrical Costs | E431: =G401*(1+E430) -> 0
D432: Markup on Electrical Costs | E432: 0.25
D433: Electrical Sell Price | E433: =E431*(1+E432) -> 0
D436: TOTAL SELL PRICE | E436: =E421+E433+E410+E427 -> 0
D437: GROSS MARGIN | E437: =(E436-(E431+E417))/E436 -> #DIV/0!
D440: Markup on Total Sell Price | E440: 0.15
...
